<?xml version="1.0" encoding="UTF-8"?>
<!-- Generated by org.testng.reporters.JUnitReportReporter -->
<testsuite hostname="Koushik" failures="1" tests="6" name="TestPackage.login" time="25.544" errors="0" timestamp="2025-10-05T19:02:02 IST" skipped="0">
  <testcase classname="TestPackage.login" name="loginTest" time="3.975"/>
  <testcase classname="TestPackage.login" name="loginTest" time="3.442"/>
  <testcase classname="TestPackage.login" name="loginTest" time="3.089"/>
  <testcase classname="TestPackage.login" name="loginTest" time="3.079"/>
  <testcase classname="TestPackage.login" name="loginTest" time="3.564">
    <failure message="expected [https://www.saucedemo.com/inventory.html] but found [https://www.saucedemo.com/]" type="java.lang.AssertionError">
      <![CDATA[java.lang.AssertionError: expected [https://www.saucedemo.com/inventory.html] but found [https://www.saucedemo.com/]
at org.testng.Assert.fail(Assert.java:111)
at org.testng.Assert.failNotEquals(Assert.java:1590)
at org.testng.Assert.assertEqualsImpl(Assert.java:150)
at org.testng.Assert.assertEquals(Assert.java:132)
at org.testng.Assert.assertEquals(Assert.java:656)
at org.testng.Assert.assertEquals(Assert.java:666)
at Pages.loginPage.loginSwaglab(loginPage.java:32)
at TestPackage.login.loginTest(login.java:26)
at java.base/jdk.internal.reflect.DirectMethodHandleAccessor.invoke(DirectMethodHandleAccessor.java:103)
at java.base/java.lang.reflect.Method.invoke(Method.java:580)
at org.testng.internal.invokers.MethodInvocationHelper.invokeMethod(MethodInvocationHelper.java:141)
at org.testng.internal.invokers.TestInvoker.invokeMethod(TestInvoker.java:687)
at org.testng.internal.invokers.TestInvoker.invokeTestMethod(TestInvoker.java:230)
at org.testng.internal.invokers.MethodRunner.runInSequence(MethodRunner.java:63)
at org.testng.internal.invokers.TestInvoker$MethodInvocationAgent.invoke(TestInvoker.java:995)
at org.testng.internal.invokers.TestInvoker.invokeTestMethods(TestInvoker.java:203)
at org.testng.internal.invokers.TestMethodWorker.invokeTestMethods(TestMethodWorker.java:154)
at org.testng.internal.invokers.TestMethodWorker.run(TestMethodWorker.java:134)
at java.base/java.util.ArrayList.forEach(ArrayList.java:1596)
at org.testng.TestRunner.privateRun(TestRunner.java:741)
at org.testng.TestRunner.run(TestRunner.java:616)
at org.testng.SuiteRunner.runTest(SuiteRunner.java:421)
at org.testng.SuiteRunner$SuiteWorker.run(SuiteRunner.java:463)
at org.testng.internal.thread.ThreadUtil.lambda$execute$0(ThreadUtil.java:64)
at java.base/java.util.concurrent.FutureTask.run(FutureTask.java:317)
at java.base/java.util.concurrent.ThreadPoolExecutor.runWorker(ThreadPoolExecutor.java:1144)
at java.base/java.util.concurrent.ThreadPoolExecutor$Worker.run(ThreadPoolExecutor.java:642)
at java.base/java.lang.Thread.run(Thread.java:1583)
]]>
    </failure>
  </testcase> <!-- loginTest -->
  <testcase classname="TestPackage.login" name="loginTest" time="8.395"/>
</testsuite> <!-- TestPackage.login -->
